2019-12-20 14:05:33,968 mysql_util.py[line:35] ERROR (2003, "Can't connect to MySQL server on '127.0.0.1' ([WinError 10061] 由于目标计算机积极拒绝，无法连接。)")
Traceback (most recent call last):
  File "D:\Program Files\Python38\lib\site-packages\pymysql\connections.py", line 581, in connect
    sock = socket.create_connection(
  File "D:\Program Files\Python38\lib\socket.py", line 807, in create_connection
    raise err
  File "D:\Program Files\Python38\lib\socket.py", line 796, in create_connection
    sock.connect(sa)
ConnectionRefusedError: [WinError 10061] 由于目标计算机积极拒绝，无法连接。

During handling of the above exception, another exception occurred:

Traceback (most recent call last):
  File "G:/PycharmCode/PersonalMattersApi/common/mysql_util.py", line 24, in __init__
    self.conn = pymysql.connect(host=host, user=username, passwd=password, db=dbname, port=int(port),
  File "D:\Program Files\Python38\lib\site-packages\pymysql\__init__.py", line 94, in Connect
    return Connection(*args, **kwargs)
  File "D:\Program Files\Python38\lib\site-packages\pymysql\connections.py", line 325, in __init__
    self.connect()
  File "D:\Program Files\Python38\lib\site-packages\pymysql\connections.py", line 630, in connect
    raise exc
pymysql.err.OperationalError: (2003, "Can't connect to MySQL server on '127.0.0.1' ([WinError 10061] 由于目标计算机积极拒绝，无法连接。)")
2019-12-20 14:40:57,497 mysql_util.py[line:35] ERROR (1130, "Host 'windows10.microdone.cn' is not allowed to connect to this MySQL server")
Traceback (most recent call last):
  File "G:/PycharmCode/PersonalMattersApi/common/mysql_util.py", line 24, in __init__
    self.conn = pymysql.connect(host=host, user=username, passwd=password, db=dbname, port=int(port),
  File "D:\Program Files\Python38\lib\site-packages\pymysql\__init__.py", line 94, in Connect
    return Connection(*args, **kwargs)
  File "D:\Program Files\Python38\lib\site-packages\pymysql\connections.py", line 325, in __init__
    self.connect()
  File "D:\Program Files\Python38\lib\site-packages\pymysql\connections.py", line 598, in connect
    self._get_server_information()
  File "D:\Program Files\Python38\lib\site-packages\pymysql\connections.py", line 975, in _get_server_information
    packet = self._read_packet()
  File "D:\Program Files\Python38\lib\site-packages\pymysql\connections.py", line 684, in _read_packet
    packet.check_error()
  File "D:\Program Files\Python38\lib\site-packages\pymysql\protocol.py", line 220, in check_error
    err.raise_mysql_exception(self._data)
  File "D:\Program Files\Python38\lib\site-packages\pymysql\err.py", line 109, in raise_mysql_exception
    raise errorclass(errno, errval)
pymysql.err.InternalError: (1130, "Host 'windows10.microdone.cn' is not allowed to connect to this MySQL server")
